<?xml version="1.0" ?>
<!-- =================================================================================== -->
<!-- |    This document was autogenerated by xacro from g500ARM5.urdf.xacro            | -->
<!-- |    EDITING THIS FILE BY HAND IS NOT RECOMMENDED                                 | -->
<!-- =================================================================================== -->
<robot name="arm5e" xmlns:xacro="http://www.ros.org/wiki/xacro">
  
  <link name="kinematic_base">
    <!-- kinematic base of the robot -->
  </link>
  <link name="part1">
    <visual>
      <origin rpy="3.141592654 0 0" xyz="0.0 0 -0.13"/>
      <geometry>
        <mesh filename="robot/ARM5E/ARM5E_part1.osg"/>
      </geometry>
    </visual>
  </link>
  <joint name="Slew" type="continuous">
    <parent link="kinematic_base"/>
    <child link="part1"/>
    <axis xyz="0 0 1"/>
    <origin rpy="0 0 0" xyz="0 0 0"/>
    <!-- La distancia base_link - base cinematica es 1.08. -->
    <limit effort="1000.0" lower="-1.570796327" upper="0.5488" velocity="1.0"/>
  </joint>
  <link name="part2">
    <visual>
      <origin rpy="1.570796327 0 -0.087262726" xyz="0 0 0"/>
      <!-- rpy="1.57 -0.209 0" xyz="0 0 0" -->
      <geometry>
        <mesh filename="robot/ARM5E/ARM5E_part2.osg"/>
      </geometry>
    </visual>
  </link>
  <joint name="Shoulder" type="continuous">
    <parent link="part1"/>
    <child link="part2"/>
    <axis xyz="0 0 1"/>
    <origin rpy="1.570796327 0 0" xyz="0.08052 0 0"/>
    <limit effort="1000.0" lower="0" upper="1.58665" velocity="1.0"/>
  </joint>
  <link name="part3">
    <visual>
      <origin rpy="1.570796327 0 0.4014" xyz="0 0 0"/>
      <geometry>
        <mesh filename="robot/ARM5E/ARM5E_part3.osg"/>
      </geometry>
    </visual>
  </link>
  <joint name="Elbow" type="continuous">
    <parent link="part2"/>
    <child link="part3"/>
    <axis xyz="0 0 1"/>
    <origin rpy="0 0 0.139277274" xyz="0.438492379277 0.0614700067987 0"/>
    <limit effort="1000.0" lower="0" upper="2.15294" velocity="1.0"/>
  </joint>
  <link name="part4_base">
    <visual>
      <origin rpy="0 -1.570796327 0" xyz="0 0 -0.028"/>
      <!-- TEMPORAL: para compensar la pieza que falta -->
      <geometry>
        <mesh filename="robot/ARM5E/ARM5E_part4_base.osg"/>
      </geometry>
    </visual>
  </link>
  <joint name="JawRotate" type="continuous">
    <parent link="part3"/>
    <child link="part4_base"/>
    <axis xyz="0 0 1"/>
    <origin rpy="1.570796327 0 1.972222055" xyz="0.349117258152 0.058023572508 0"/>
  </joint>

  <link name="end_effector"></link>
  <link name="new_end_effector"></link>
  <joint name="eef_to_new_eef" type="fixed">
    <parent link="end_effector"/>
    <child link="new_end_effector"/>
    <origin rpy="0 0 0" xyz="0 0 0.062"/>
  </joint>
  <link name="ar_marker"></link>
  <joint name="eef_to_marker" type="fixed">
    <parent link="new_end_effector"/>
    <child link="ar_marker"/>
    <origin rpy="-1.57 0 0" xyz="0 0.055 -0.201"/>
  </joint>



  <joint name="part4_base_to_end_effector" type="fixed">
    <parent link="part4_base"/>
    <child link="end_effector"/>
    <origin rpy="0 0 0" xyz="0 0 0.1485"/>
  </joint>
  <link name="part4_jaw1">
    <visual>
      <origin rpy="0 -1.570796327 0" xyz="0 0 0"/>
      <geometry>
        <mesh filename="robot/ARM5E/ARM5E_part4_jaw1.osg"/>
      </geometry>
    </visual>
  </link>
  <joint name="JawOpening" type="continuous">
    <parent link="part4_base"/>
    <child link="part4_jaw1"/>
    <axis xyz="0 -1 0"/>
    <origin rpy="0 0 0" xyz="-0.04 0 0.045"/>
    <!-- x era 0.07-->
    <limit effort="1000.0" lower="-0.05816" upper="1.337696" velocity="1.0"/>
  </joint>
  <link name="part4_jaw2">
    <visual>
      <origin rpy="0 -1.570796327 0" xyz="0 0 0"/>
      <geometry>
        <mesh filename="robot/ARM5E/ARM5E_part4_jaw2.osg"/>
      </geometry>
    </visual>
  </link>
  <joint name="part4_to_link4_jaw2" type="continuous">
    <parent link="part4_base"/>
    <child link="part4_jaw2"/>
    <axis xyz="0 1 0"/>
    <origin rpy="0 0 0" xyz="0.04 0 0.0450"/>
    <!-- x era 0.07-->
    <mimic joint="JawOpening" multiplier="1" offset="0"/>
  </joint>
</robot>

