<?xml version="1.0"?>
<robot name="arm5e_gripper">
  <link name="part4_base">
    <visual>
      <origin rpy="0 -1.570796327 1.57" xyz="0 0 -0.028"/>
      <geometry>
        <mesh filename="robot/ARM5E/ARM5E_part4_base_green.osg"/>
      </geometry>
    </visual>
  </link>
  <link name="end_effector">
  </link>
  <joint name="part4_base_to_end_effector" type="fixed">
    <parent link="part4_base"/>
    <child link="end_effector"/>
    <origin rpy="0 0 0" xyz="0 0 0.1485"/>
  </joint>
  <link name="part4_jaw1">
    <visual>
      <origin rpy="0 -1.570796327 1.570796327" xyz="0 0 0"/>
      <geometry>
        <mesh filename="robot/ARM5E/ARM5E_part4_jaw1long.osg"/>
      </geometry>
    </visual>
    <collision>
	  <geometry>
        <mesh filename="robot/ARM5E/ARM5E_part4_jaw1long_collisions.osg"/>
      </geometry>
    </collision>
  </link>
  <joint name="JawOpening" type="continuous">
    <parent link="part4_base"/>
    <child link="part4_jaw1"/>
    <axis xyz="1 0 0"/>
    <origin rpy="0 0 0" xyz="0 -0.04 0.045"/>
    <!-- x era 0.07-->
    <limit effort="1000.0" lower="-0.05816" upper="1.337696" velocity="1.0"/>
  </joint>
  <link name="part4_jaw2">
    <visual>
      <origin rpy="0 -1.570796327 1.570796327" xyz="0 0 0"/>
      <geometry>
        <mesh filename="robot/ARM5E/ARM5E_part4_jaw2long.osg"/>
      </geometry>
    </visual>
    <collision>
	  <geometry>
        <mesh filename="robot/ARM5E/ARM5E_part4_jaw2long_collisions.osg"/>
      </geometry>
    </collision>
  </link>
  <joint name="part4_to_link4_jaw2" type="continuous">
    <parent link="part4_base"/>
    <child link="part4_jaw2"/>
    <axis xyz="-1 0 0"/>
    <origin rpy="0 0 0" xyz="0 0.04 0.0450"/>
    <!-- x era 0.07-->
    <mimic joint="JawOpening" multiplier="1" offset="0"/>
  </joint>

</robot>
